<?xml version="1.0" encoding="utf-8"?>
<!-- This URDF was automatically created by SolidWorks to URDF Exporter! Originally created by Stephen Brawner (brawner@gmail.com) 
     Commit Version: 1.6.0-4-g7f85cfe  Build Version: 1.6.7995.38578
     For more information, please see http://wiki.ros.org/sw_urdf_exporter -->
<robot xmlns:xacro="http://www.ros.org/wiki/xacro">
  <link name="base_link">
    <inertial>
      <origin
        xyz="0.000155648729898483 0.0272260605212869 -0.0160506872006314"
        rpy="0 0 0" />
      <mass
        value="2.39673115484037" />
      <inertia
        ixx="0.0649359676606888"
        ixy="-3.23309878937406E-06"
        ixz="-1.5801707361801E-05"
        iyy="0.151052606287283"
        iyz="0.00348651743736052"
        izz="0.0913994713096704" />
    </inertial>
    <visual>
      <origin
        xyz="0 0 0"
        rpy="0 0 0" />
      <geometry>
        <mesh
          filename="package://alfred/meshes/base_link.STL" />
      </geometry>
      <material
        name="">
        <color
          rgba="0.792156862745098 0.819607843137255 0.933333333333333 1" />
      </material>
    </visual>
    <collision>
      <origin
        xyz="0 0 0"
        rpy="0 0 0" />
      <geometry>
        <mesh
          filename="package://alfred/meshes/base_link.STL" />
      </geometry>
    </collision>
  </link>
  <link name="right_wheel">
    <inertial>
      <origin
        xyz="-1.23207411052706E-06 -1.81423617004461E-07 3.7972214399995E-05"
        rpy="0 0 0" />
      <mass
        value="0.870754309555774" />
      <inertia
        ixx="0.00147130345611962"
        ixy="1.67237487338077E-07"
        ixz="-3.50030378056275E-05"
        iyy="0.0014701923478899"
        iyz="-5.15421732401467E-06"
        izz="0.00254895254910207" />
    </inertial>
    <visual>
      <origin
        xyz="0 0 0"
        rpy="0 0 0" />
      <geometry>
        <mesh
          filename="package://alfred/meshes/right_wheel.STL" />
      </geometry>
      <material
        name="">
        <color
          rgba="0.627450980392157 0.627450980392157 0.627450980392157 1" />
      </material>
    </visual>
    <collision>
      <origin
        xyz="0 0 0"
        rpy="0 0 0" />
      <geometry>
        <mesh
          filename="package://alfred/meshes/right_wheel.STL" />
      </geometry>
    </collision>
  </link>
  <joint name="rightwheel"
    type="continuous">
    <origin
      xyz="-0.26018 0.029145 0.015932"
      rpy="1.3494 -1.421 -1.3518" />
    <parent
      link="base_link" />
    <child
      link="right_wheel" />
    <axis
      xyz="0.032429 0.0047752 -0.99946" />
    <limit
      effort="10"
      velocity="10" />
    <dynamics
      damping="0.1"
      friction="0.1" />
  </joint>
  <link name="left_wheel">
    <inertial>
      <origin
        xyz="-2.77555756156289E-17 0 0.0264620073692989"
        rpy="0 0 0" />
      <mass
        value="0.870754309555773" />
      <inertia
        ixx="0.0014701677220743"
        ixy="1.26537954205295E-20"
        ixz="-1.12236956324533E-20"
        iyy="0.0014701677220743"
        iyz="1.35697148354514E-20"
        izz="0.00255011290896298" />
    </inertial>
    <visual>
      <origin
        xyz="0 0 0"
        rpy="0 0 0" />
      <geometry>
        <mesh
          filename="package://alfred/meshes/left_wheel.STL" />
      </geometry>
      <material
        name="">
        <color
          rgba="0.627450980392157 0.627450980392157 0.627450980392157 1" />
      </material>
    </visual>
    <collision>
      <origin
        xyz="0 0 0"
        rpy="0 0 0" />
      <geometry>
        <mesh
          filename="package://alfred/meshes/left_wheel.STL" />
      </geometry>
    </collision>
  </link>
  <joint name="leftwheel"
    type="revolute">
    <origin
      xyz="0.28572 0.023368 0.015582"
      rpy="3.1416 1.5708 0" />
    <parent
      link="base_link" />
    <child
      link="left_wheel" />
    <axis
      xyz="0 0 1" />
    <limit
      lower="0"
      upper="0"
      effort="10"
      velocity="10" />
    <dynamics
      damping="0.1"
      friction="0.1" />
  </joint>
  <link name="caster_wheel_1">
    <inertial>
      <origin
        xyz="0.00541387546373896 -0.00362424514238398 2.31731049905037E-05"
        rpy="0 0 0" />
      <mass
        value="0.00813681147059775" />
      <inertia
        ixx="6.88663031872148E-07"
        ixy="1.39258615440213E-07"
        ixz="-1.73175409558386E-09"
        iyy="1.31727307889561E-06"
        iyz="4.4442362691297E-10"
        izz="1.14243246485713E-06" />
    </inertial>
    <visual>
      <origin
        xyz="0 0 0"
        rpy="0 0 0" />
      <geometry>
        <mesh
          filename="package://alfred/meshes/caster_wheel_1.STL" />
      </geometry>
      <material
        name="">
        <color
          rgba="0.796078431372549 0.796078431372549 0.796078431372549 1" />
      </material>
    </visual>
    <collision>
      <origin
        xyz="0 0 0"
        rpy="0 0 0" />
      <geometry>
        <mesh
          filename="package://alfred/meshes/caster_wheel_1.STL" />
      </geometry>
    </collision>
  </link>
  <joint name="casterwheel1"
    type="fixed">
    <origin
      xyz="-0.25509 -0.00050335 -0.1737"
      rpy="-0.34384 -1.5669 0.34384" />
    <parent
      link="base_link" />
    <child
      link="caster_wheel_1" />
    <axis
      xyz="0 0 0" />
    <limit
      effort="10"
      velocity="10" />
  </joint>
  <link name="caster_wheel_01">
    <inertial>
      <origin
        xyz="1.38777878078145E-17 -3.46944695195361E-18 -5.55111512312578E-17"
        rpy="0 0 0" />
      <mass
        value="0.015690813753013" />
      <inertia
        ixx="1.58355334748907E-06"
        ixy="-9.24254365042994E-13"
        ixz="-3.01208974436573E-09"
        iyy="1.58354152013519E-06"
        iyz="2.33961114635756E-10"
        izz="2.34600673978302E-06" />
    </inertial>
    <visual>
      <origin
        xyz="0 0 0"
        rpy="0 0 0" />
      <geometry>
        <mesh
          filename="package://alfred/meshes/caster_wheel_01.STL" />
      </geometry>
      <material
        name="">
        <color
          rgba="0.792156862745098 0.819607843137255 0.933333333333333 1" />
      </material>
    </visual>
    <collision>
      <origin
        xyz="0 0 0"
        rpy="0 0 0" />
      <geometry>
        <mesh
          filename="package://alfred/meshes/caster_wheel_01.STL" />
      </geometry>
    </collision>
  </link>
  <joint name="casterwheel01"
    type="revolute">
    <origin
      xyz="0.020025 -0.02806 0.00012279"
      rpy="2.5881E-05 0.0003332 0.076219" />
    <parent
      link="caster_wheel_1" />
    <child
      link="caster_wheel_01" />
    <axis
      xyz="0.0039504 -0.00030685 -0.99999" />
    <limit
      lower="0"
      upper="0"
      effort="10"
      velocity="10" />
    <dynamics
      damping="0.1"
      friction="0.1" />
  </joint>
  <link name="caster_wheel_2">
    <inertial>
      <origin
        xyz="-0.00538390592464583 0.00366600876644682 0.000140264395563694"
        rpy="0 0 0" />
      <mass
        value="0.00813681147059776" />
      <inertia
        ixx="6.91141686832364E-07"
        ixy="1.44060987188059E-07"
        ixz="1.15107747536255E-08"
        iyy="1.31508135810754E-06"
        iyz="-3.53798068585968E-09"
        izz="1.14214553068499E-06" />
    </inertial>
    <visual>
      <origin
        xyz="0 0 0"
        rpy="0 0 0" />
      <geometry>
        <mesh
          filename="package://alfred/meshes/caster_wheel_2.STL" />
      </geometry>
      <material
        name="">
        <color
          rgba="0.796078431372549 0.796078431372549 0.796078431372549 1" />
      </material>
    </visual>
    <collision>
      <origin
        xyz="0 0 0"
        rpy="0 0 0" />
      <geometry>
        <mesh
          filename="package://alfred/meshes/caster_wheel_2.STL" />
      </geometry>
    </collision>
  </link>
  <joint name="casterwheel2"
    type="fixed">
    <origin
      xyz="-0.25509 -0.00050335 0.15807"
      rpy="0.34373 1.544 -2.7978" />
    <parent
      link="base_link" />
    <child
      link="caster_wheel_2" />
    <axis
      xyz="0 0 0" />
    <limit
      effort="10"
      velocity="10" />
    <dynamics
      damping="0.1"
      friction="0.1" />
  </joint>
  <link name="caster_wheel_02">
    <inertial>
      <origin
        xyz="0 0 -5.55111512312578E-17"
        rpy="0 0 0" />
      <mass
        value="0.015690813753013" />
      <inertia
        ixx="1.58431628208126E-06"
        ixy="-6.20213445772099E-10"
        ixz="-2.4285964552773E-08"
        iyy="1.58403789642135E-06"
        iyz="1.94396307842574E-08"
        izz="2.34474742890467E-06" />
    </inertial>
    <visual>
      <origin
        xyz="0 0 0"
        rpy="0 0 0" />
      <geometry>
        <mesh
          filename="package://alfred/meshes/caster_wheel_02.STL" />
      </geometry>
      <material
        name="">
        <color
          rgba="0.792156862745098 0.819607843137255 0.933333333333333 1" />
      </material>
    </visual>
    <collision>
      <origin
        xyz="0 0 0"
        rpy="0 0 0" />
      <geometry>
        <mesh
          filename="package://alfred/meshes/caster_wheel_02.STL" />
      </geometry>
    </collision>
  </link>
  <joint name="casterwheel02"
    type="revolute">
    <origin
      xyz="-0.0198 0.028214 0.00055628"
      rpy="0.0097515 0.012182 -2.4756" />
    <parent
      link="caster_wheel_2" />
    <child
      link="caster_wheel_02" />
    <axis
      xyz="0.031878 -0.025517 -0.99917" />
    <limit
      lower="0"
      upper="0"
      effort="10"
      velocity="10" />
    <dynamics
      damping="0.1"
      friction="0.1" />
  </joint>
  <link name="caster_wheel_3">
    <inertial>
      <origin
        xyz="0.00538392776946806 -0.00366600751332797 -0.000139456326991423"
        rpy="0 0 0" />
      <mass
        value="0.00813681147059775" />
      <inertia
        ixx="6.91159638566033E-07"
        ixy="1.44053452925748E-07"
        ixz="1.1859686889877E-08"
        iyy="1.31508156693025E-06"
        iyz="-3.82016508907123E-09"
        izz="1.14212737012861E-06" />
    </inertial>
    <visual>
      <origin
        xyz="0 0 0"
        rpy="0 0 0" />
      <geometry>
        <mesh
          filename="package://alfred/meshes/caster_wheel_3.STL" />
      </geometry>
      <material
        name="">
        <color
          rgba="0.627450980392157 0.627450980392157 0.627450980392157 1" />
      </material>
    </visual>
    <collision>
      <origin
        xyz="0 0 0"
        rpy="0 0 0" />
      <geometry>
        <mesh
          filename="package://alfred/meshes/caster_wheel_3.STL" />
      </geometry>
    </collision>
  </link>
  <joint name="casterwheel3"
    type="fixed">
    <origin
      xyz="0.25514 -0.00050335 0.15807"
      rpy="-2.8117 -1.5429 2.8116" />
    <parent
      link="base_link" />
    <child
      link="caster_wheel_3" />
    <axis
      xyz="0 0 0" />
    <limit
      effort="10"
      velocity="10" />
  </joint>
  <link name="caster_wheel_03">
    <inertial>
      <origin
        xyz="2.77555756156289E-17 -5.55111512312578E-17 0"
        rpy="0 0 0" />
      <mass
        value="0.015690813753013" />
      <inertia
        ixx="1.58440199551892E-06"
        ixy="-6.97440399293903E-10"
        ixz="2.55914182693428E-08"
        iyy="1.58410669697378E-06"
        iyz="-2.07408605940244E-08"
        izz="2.3445929149146E-06" />
    </inertial>
    <visual>
      <origin
        xyz="0 0 0"
        rpy="0 0 0" />
      <geometry>
        <mesh
          filename="package://alfred/meshes/caster_wheel_03.STL" />
      </geometry>
      <material
        name="">
        <color
          rgba="0.792156862745098 0.819607843137255 0.933333333333333 1" />
      </material>
    </visual>
    <collision>
      <origin
        xyz="0 0 0"
        rpy="0 0 0" />
      <geometry>
        <mesh
          filename="package://alfred/meshes/caster_wheel_03.STL" />
      </geometry>
    </collision>
  </link>
  <joint name="casterwheel03"
    type="revolute">
    <origin
      xyz="0.019891 -0.028498 -0.00059982"
      rpy="-0.010622 -0.013105 0.67212" />
    <parent
      link="caster_wheel_3" />
    <child
      link="caster_wheel_03" />
    <axis
      xyz="0.033595 -0.027227 0.99906" />
    <limit
      lower="0"
      upper="0"
      effort="10"
      velocity="10" />
    <dynamics
      damping="0.1"
      friction="0.1" />
  </joint>
  <link name="caster_wheel_4">
    <inertial>
      <origin
        xyz="0.00541389822389198 -0.00362424516763937 -1.70401862173986E-05"
        rpy="0 0 0" />
      <mass
        value="0.00813681147059775" />
      <inertia
        ixx="6.88662330084556E-07"
        ixy="1.3925808494676E-07"
        ixz="1.63722193057523E-09"
        iyy="1.31727308049548E-06"
        iyz="-5.87375749999557E-10"
        izz="1.14243316504485E-06" />
    </inertial>
    <visual>
      <origin
        xyz="0 0 0"
        rpy="0 0 0" />
      <geometry>
        <mesh
          filename="package://alfred/meshes/caster_wheel_4.STL" />
      </geometry>
      <material
        name="">
        <color
          rgba="0.627450980392157 0.627450980392157 0.627450980392157 1" />
      </material>
    </visual>
    <collision>
      <origin
        xyz="0 0 0"
        rpy="0 0 0" />
      <geometry>
        <mesh
          filename="package://alfred/meshes/caster_wheel_4.STL" />
      </geometry>
    </collision>
  </link>
  <joint name="casterwheel4"
    type="fixed">
    <origin
      xyz="0.25514 -0.00050335 -0.1737"
      rpy="-2.8116 -1.5668 2.8116" />
    <parent
      link="base_link" />
    <child
      link="caster_wheel_4" />
    <axis
      xyz="0 0 0" />
    <limit
      effort="10"
      velocity="10" />
    <dynamics
      damping="0.1"
      friction="0.1" />
  </joint>
  <link name="caster_wheel_04">
    <inertial>
      <origin
        xyz="0 0 0"
        rpy="0 0 0" />
      <mass
        value="0.015690813753013" />
      <inertia
        ixx="1.58355473055731E-06"
        ixy="-1.04217870201633E-12"
        ixz="3.18232739445097E-09"
        iyy="1.5835415301184E-06"
        iyz="-2.4969889564166E-10"
        izz="2.34600534673159E-06" />
    </inertial>
    <visual>
      <origin
        xyz="0 0 0"
        rpy="0 0 0" />
      <geometry>
        <mesh
          filename="package://alfred/meshes/caster_wheel_04.STL" />
      </geometry>
      <material
        name="">
        <color
          rgba="0.792156862745098 0.819607843137255 0.933333333333333 1" />
      </material>
    </visual>
    <collision>
      <origin
        xyz="0 0 0"
        rpy="0 0 0" />
      <geometry>
        <mesh
          filename="package://alfred/meshes/caster_wheel_04.STL" />
      </geometry>
    </collision>
  </link>
  <joint name="casterwheel04"
    type="revolute">
    <origin
      xyz="0.020119 -0.028343 -0.00014448"
      rpy="-3.077E-05 -0.00039215 0.077005" />
    <parent
      link="caster_wheel_4" />
    <child
      link="caster_wheel_04" />
    <axis
      xyz="0.0041737 -0.00032749 0.99999" />
    <limit
      lower="0"
      upper="0"
      effort="10"
      velocity="10" />
    <dynamics
      damping="0.1"
      friction="0.1" />
  </joint>
  <link name="Lidar">
    <inertial>
      <origin
        xyz="7.60771350699907E-05 0.000173648233309398 -0.000166043562173118"
        rpy="0 0 0" />
      <mass
        value="0.0250181551110355" />
      <inertia
        ixx="4.83347969282592E-06"
        ixy="6.56950320024398E-09"
        ixz="-6.28180138828127E-09"
        iyy="6.68909322972297E-06"
        iyz="1.73950484244045E-06"
        izz="6.84494033009201E-06" />
    </inertial>
    <visual>
      <origin
        xyz="0 0 0"
        rpy="0 0 0" />
      <geometry>
        <mesh
          filename="package://alfred/meshes/Lidar.STL" />
      </geometry>
      <material
        name="">
        <color
          rgba="0.627450980392157 0.627450980392157 0.627450980392157 1" />
      </material>
    </visual>
    <collision>
      <origin
        xyz="0 0 0"
        rpy="0 0 0" />
      <geometry>
        <mesh
          filename="package://alfred/meshes/Lidar.STL" />
      </geometry>
    </collision>
  </link>
  <joint name="Lidar"
    type="revolute">
    <origin
      xyz="-0.0010173 0.18784 0.16863"
      rpy="2.3338 0 3.1416" />
    <parent
      link="base_link" />
    <child
      link="Lidar" />
    <axis
      xyz="0 -0.6911 -0.72276" />
    <limit
      lower="0"
      upper="0"
      effort="10"
      velocity="10" />
  </joint>
</robot>