<?xml version="1.0" encoding="utf-8"?>
<!-- This URDF was automatically created by SolidWorks to URDF Exporter! Originally created by Stephen Brawner (brawner@gmail.com) 
     Commit Version: 1.6.0-4-g7f85cfe  Build Version: 1.6.7995.38578
     For more information, please see http://wiki.ros.org/sw_urdf_exporter -->
<robot>
  <link name="base_link">
    <inertial>
      <origin
        xyz="0.0065132540264814 0.00136276106591204 0.15823095354149"
        rpy="0 0 0" />
      <mass
        value="32.5370047332158" />
      <inertia
        ixx="1.86782747849832"
        ixy="-0.000933522235429167"
        ixz="-0.0965412925988386"
        iyy="1.43980812088733"
        iyz="0.00636285334393433"
        izz="1.50682356346103" />
    </inertial>
    <visual>
      <origin
        xyz="0 0 0"
        rpy="0 0 0" />
      <geometry>
        <mesh
          filename="package://alfred/meshes/base_link.STL" />
      </geometry>
      <material
        name="">
        <color
          rgba="0.792156862745098 0.819607843137255 0.933333333333333 1" />
      </material>
    </visual>
    <collision>
      <origin
        xyz="0 0 0"
        rpy="0 0 0" />
      <geometry>
        <mesh
          filename="package://alfred/meshes/base_link.STL" />
      </geometry>
    </collision>
  </link>
  <link name="right_wheel">
    <inertial>
      <origin
        xyz="4.44089209850063E-16 5.55111512312578E-17 3.79926307011447E-05"
        rpy="0 0 0" />
      <mass
        value="0.870754309555773" />
      <inertia
        ixx="0.0014701677220743"
        ixy="5.47076577627259E-19"
        ixz="3.30821336876901E-21"
        iyy="0.0014701677220743"
        iyz="-7.28479562221043E-18"
        izz="0.00255011290896298" />
    </inertial>
    <visual>
      <origin
        xyz="0 0 0"
        rpy="0 0 0" />
      <geometry>
        <mesh
          filename="package://alfred/meshes/right_wheel.STL" />
      </geometry>
      <material
        name="">
        <color
          rgba="0.964705882352941 0.964705882352941 0.952941176470588 1" />
      </material>
    </visual>
    <collision>
      <origin
        xyz="0 0 0"
        rpy="0 0 0" />
      <geometry>
        <mesh
          filename="package://alfred/meshes/right_wheel.STL" />
      </geometry>
    </collision>
  </link>
  <joint name="rightwheel"
    type="continuous">
    <origin
      xyz="0.015963 0.25598 0.029318"
      rpy="-1.5708 0 0" />
    <parent
      link="base_link" />
    <child
      link="right_wheel" />
    <axis
      xyz="0 0 1" />
  </joint>
  <link name="left_wheel">
    <inertial>
      <origin
        xyz="2.22044604925031E-16 1.11022302462516E-16 -3.79926307011447E-05"
        rpy="0 0 0" />
      <mass
        value="0.870754309555774" />
      <inertia
        ixx="0.0014701677220743"
        ixy="9.09397953815072E-22"
        ixz="-2.00483216474024E-19"
        iyy="0.0014701677220743"
        iyz="-3.97186169090865E-18"
        izz="0.00255011290896299" />
    </inertial>
    <visual>
      <origin
        xyz="0 0 0"
        rpy="0 0 0" />
      <geometry>
        <mesh
          filename="package://alfred/meshes/left_wheel.STL" />
      </geometry>
      <material
        name="">
        <color
          rgba="0.964705882352941 0.964705882352941 0.952941176470588 1" />
      </material>
    </visual>
    <collision>
      <origin
        xyz="0 0 0"
        rpy="0 0 0" />
      <geometry>
        <mesh
          filename="package://alfred/meshes/left_wheel.STL" />
      </geometry>
    </collision>
  </link>
  <joint name="leftwheel"
    type="continuous">
    <origin
      xyz="0.015963 -0.25602 0.029318"
      rpy="-1.5708 0 0" />
    <parent
      link="base_link" />
    <child
      link="left_wheel" />
    <axis
      xyz="0 0 -1" />
  </joint>
  <link name="caster_1">
    <inertial>
      <origin
        xyz="0 5.55111512312578E-17 -1.66533453693773E-16"
        rpy="0 0 0" />
      <mass
        value="0.015690813753013" />
      <inertia
        ixx="1.58354144834464E-06"
        ixy="-1.80555932286303E-35"
        ixz="9.43612260945113E-22"
        iyy="1.58354144834464E-06"
        iyz="-2.42372869581876E-21"
        izz="2.34601871071801E-06" />
    </inertial>
    <visual>
      <origin
        xyz="0 0 0"
        rpy="0 0 0" />
      <geometry>
        <mesh
          filename="package://alfred/meshes/caster_1.STL" />
      </geometry>
      <material
        name="">
        <color
          rgba="0.792156862745098 0.819607843137255 0.933333333333333 1" />
      </material>
    </visual>
    <collision>
      <origin
        xyz="0 0 0"
        rpy="0 0 0" />
      <geometry>
        <mesh
          filename="package://alfred/meshes/caster_1.STL" />
      </geometry>
    </collision>
  </link>
  <joint name="caster 1"
    type="fixed">
    <origin
      xyz="0.17826 -0.25504 -0.02882"
      rpy="-1.5708 0 0" />
    <parent
      link="base_link" />
    <child
      link="caster_1" />
    <axis
      xyz="0 0 0" />
  </joint>
  <link name="caster_2">
    <inertial>
      <origin
        xyz="0 -3.60822483003176E-16 -1.11022302462516E-16"
        rpy="0 0 0" />
      <mass
        value="0.0156908137530131" />
      <inertia
        ixx="1.58354144834465E-06"
        ixy="-1.05324293833677E-34"
        ixz="-1.45084165925365E-20"
        iyy="1.58354144834465E-06"
        iyz="5.58148465464623E-21"
        izz="2.34601871071802E-06" />
    </inertial>
    <visual>
      <origin
        xyz="0 0 0"
        rpy="0 0 0" />
      <geometry>
        <mesh
          filename="package://alfred/meshes/caster_2.STL" />
      </geometry>
      <material
        name="">
        <color
          rgba="0.792156862745098 0.819607843137255 0.933333333333333 1" />
      </material>
    </visual>
    <collision>
      <origin
        xyz="0 0 0"
        rpy="0 0 0" />
      <geometry>
        <mesh
          filename="package://alfred/meshes/caster_2.STL" />
      </geometry>
    </collision>
  </link>
  <joint name="caster2"
    type="continuous">
    <origin
      xyz="0.17826 0.2552 -0.02882"
      rpy="-1.5708 0 0" />
    <parent
      link="base_link" />
    <child
      link="caster_2" />
    <axis
      xyz="0 0 -1" />
  </joint>
  <link name="caster_3">
    <inertial>
      <origin
        xyz="-0.0171450000000002 -2.4980018054066E-16 -1.0547118733939E-14"
        rpy="0 0 0" />
      <mass
        value="0.015690813753013" />
      <inertia
        ixx="1.58354144834464E-06"
        ixy="1.80555932286303E-35"
        ixz="-7.64322547508233E-21"
        iyy="1.58354144834464E-06"
        iyz="-2.41077504742601E-21"
        izz="2.34601871071801E-06" />
    </inertial>
    <visual>
      <origin
        xyz="0 0 0"
        rpy="0 0 0" />
      <geometry>
        <mesh
          filename="package://alfred/meshes/caster_3.STL" />
      </geometry>
      <material
        name="">
        <color
          rgba="0.792156862745098 0.819607843137255 0.933333333333333 1" />
      </material>
    </visual>
    <collision>
      <origin
        xyz="0 0 0"
        rpy="0 0 0" />
      <geometry>
        <mesh
          filename="package://alfred/meshes/caster_3.STL" />
      </geometry>
    </collision>
  </link>
  <joint name="caster3"
    type="continuous">
    <origin
      xyz="-0.13637 0.2552 -0.02882"
      rpy="-1.5708 0 0" />
    <parent
      link="base_link" />
    <child
      link="caster_3" />
    <axis
      xyz="0 0 -1" />
  </joint>
  <link name="caster_4">
    <inertial>
      <origin
        xyz="2.22044604925031E-16 -2.77555756156289E-17 1.11022302462516E-16"
        rpy="0 0 0" />
      <mass
        value="0.015690813753013" />
      <inertia
        ixx="1.58354144834464E-06"
        ixy="-1.20370621524202E-35"
        ixz="-1.44308362581399E-22"
        iyy="1.58354144834464E-06"
        iyz="-2.42551540594186E-21"
        izz="2.34601871071801E-06" />
    </inertial>
    <visual>
      <origin
        xyz="0 0 0"
        rpy="0 0 0" />
      <geometry>
        <mesh
          filename="package://alfred/meshes/caster_4.STL" />
      </geometry>
      <material
        name="">
        <color
          rgba="0.792156862745098 0.819607843137255 0.933333333333333 1" />
      </material>
    </visual>
    <collision>
      <origin
        xyz="0 0 0"
        rpy="0 0 0" />
      <geometry>
        <mesh
          filename="package://alfred/meshes/caster_4.STL" />
      </geometry>
    </collision>
  </link>
  <joint name="caster4"
    type="continuous">
    <origin
      xyz="-0.153514598447958 -0.255040666518411 -0.028820000000002"
      rpy="-1.5707963267949 0 0" />
    <parent
      link="base_link" />
    <child
      link="caster_4" />
    <axis
      xyz="0 0 -1" />
  </joint>
</robot>